use failure::Error;

fn main() -> Result<(), Error> {
}
